Workbook

Sheet 4_dpi
A1: Fungi | B1: Bacteria | C1: Number | D1: Ctrl | E1: GR | H1: dpi | I1: Finished | J1: Medium | K1: Cont
A2: R. solani | B2: Ctrl | C2: 1 | D2: 1 | E2: 3.6 | F2: 3.6 | G2: 3.6 | H2: =N$3 -> 4 | I2: 1 | J2: NA/RA10% | K2: 0 | L2: Start | M2: Heute | N2: dpi
A3: R. solani | B3: Ctrl | C3: 2 | D3: 1 | E3: 3.6 | F3: 3.6 | G3: 3.6 | H3: =N$3 -> 4 | I3: 1 | J3: NA/RA10% | K3: 0 | L3: 45950 | M3: 45954 | N3: =M3-L3 -> 4
A4: R. solani | B4: Ctrl | C4: 3 | D4: 1 | E4: 3.6 | F4: 3.6 | G4: 3.6 | H4: =N$3 -> 4 | I4: 1 | J4: NA/RA10% | K4: 0
A5: R. solani | B5: LEC | C5: 1 | D5: 0 | E5: 2.7 | F5: 3.4 | G5: 2.9 | H5: =N$3 -> 4 | I5: 0 | J5: NA/RA10% | K5: 0 | L5: NOTE: Only R. solani was assessed this day.
A6: R. solani | B6: LEC | C6: 2 | D6: 0 | E6: 3 | F6: 3.2 | G6: 3 | H6: =N$3 -> 4 | I6: 0 | J6: NA/RA10% | K6: 0
A7: R. solani | B7: LEC | C7: 3 | D7: 0 | E7: 3.9 | F7: 3.5 | G7: 3.4 | H7: =N$3 -> 4 | I7: 0 | J7: NA/RA10% | K7: 0
A8: R. solani | B8: DSM 2043 | C8: 1 | D8: 0 | E8: 3.6 | F8: 3.6 | G8: 3.6 | H8: =N$3 -> 4 | I8: 1 | J8: NA/RA10% | K8: 0
A9: R. solani | B9: DSM 2043 | C9: 2 | D9: 0 | E9: 3.5 | F9: 3.6 | G9: 3.6 | H9: =N$3 -> 4 | I9: 0 | J9: NA/RA10% | K9: 0
A10: R. solani | B10: DSM 2043 | C10: 3 | D10: 0 | E10: 3.4 | F10: 3.6 | G10: 3.5 | H10: =N$3 -> 4 | I10: 0 | J10: NA/RA10% | K10: 0
A11: R. solani | B11: DSM 2044 | C11: 1 | D11: 0 | E11: 3.6 | F11: 3.6 | G11: 3.6 | H11: =N$3 -> 4 | I11: 1 | J11: NA/RA10% | K11: 0
A12: R. solani | B12: DSM 2044 | C12: 2 | D12: 0 | E12: 3.6 | F12: 3.6 | G12: 3.6 | H12: =N$3 -> 4 | I12: 1 | J12: NA/RA10% | K12: 0
A13: R. solani | B13: DSM 2044 | C13: 3 | D13: 0 | E13: 3.6 | F13: 3.6 | G13: 3.6 | H13: =N$3 -> 4 | I13: 1 | J13: NA/RA10% | K13: 0
A14: R. solani | B14: DSM 6980 | C14: 1 | D14: 0 | E14: 3.6 | F14: 3.6 | G14: 3.6 | H14: =N$3 -> 4 | I14: 1 | J14: NA/RA10% | K14: 0
A15: R. solani | B15: DSM 6980 | C15: 2 | D15: 0 | E15: 3.6 | F15: 3.6 | G15: 3.6 | H15: =N$3 -> 4 | I15: 1 | J15: NA/RA10% | K15: 0
A16: R. solani | B16: DSM 6980 | C16: 3 | D16: 0 | E16: 3.6 | F16: 3.6 | G16: 3.6 | H16: =N$3 -> 4 | I16: 1 | J16: NA/RA10% | K16: 0

Sheet 8_dpi
A1: Fungi | B1: Bacteria | C1: Number | D1: Ctrl | E1: GR | H1: dpi | I1: Finished | J1: Medium | K1: Cont
A2: R. solani | B2: Ctrl | C2: 1 | D2: 1 | E2: 3.6 | F2: 3.6 | G2: 3.6 | H2: 4 | I2: 1 | J2: NA/RA10% | K2: 0 | L2: Start | M2: Heute | N2: dpi
A3: R. solani | B3: Ctrl | C3: 2 | D3: 1 | E3: 3.6 | F3: 3.6 | G3: 3.6 | H3: 4 | I3: 1 | J3: NA/RA10% | K3: 0 | L3: 45950 | M3: 45958 | N3: =M3-L3 -> 8
A4: R. solani | B4: Ctrl | C4: 3 | D4: 1 | E4: 3.6 | F4: 3.6 | G4: 3.6 | H4: 4 | I4: 1 | J4: NA/RA10% | K4: 0
A5: R. solani | B5: LEC | C5: 1 | D5: 0 | E5: 2.7 | F5: 3.4 | G5: 2.9 | H5: 4 | I5: 0 | J5: NA/RA10% | K5: 0 | L5: NOTE: Only P. infestans was assessed this day.
A6: R. solani | B6: LEC | C6: 2 | D6: 0 | E6: 3 | F6: 3.2 | G6: 3 | H6: 4 | I6: 0 | J6: NA/RA10% | K6: 0
A7: R. solani | B7: LEC | C7: 3 | D7: 0 | E7: 3.9 | F7: 3.5 | G7: 3.4 | H7: 4 | I7: 0 | J7: NA/RA10% | K7: 0
A8: R. solani | B8: DSM 2043 | C8: 1 | D8: 0 | E8: 3.6 | F8: 3.6 | G8: 3.6 | H8: 4 | I8: 1 | J8: NA/RA10% | K8: 0
A9: R. solani | B9: DSM 2043 | C9: 2 | D9: 0 | E9: 3.5 | F9: 3.6 | G9: 3.6 | H9: 4 | I9: 0 | J9: NA/RA10% | K9: 0
A10: R. solani | B10: DSM 2043 | C10: 3 | D10: 0 | E10: 3.4 | F10: 3.6 | G10: 3.5 | H10: 4 | I10: 0 | J10: NA/RA10% | K10: 0
A11: R. solani | B11: DSM 2044 | C11: 1 | D11: 0 | E11: 3.6 | F11: 3.6 | G11: 3.6 | H11: 4 | I11: 1 | J11: NA/RA10% | K11: 0
A12: R. solani | B12: DSM 2044 | C12: 2 | D12: 0 | E12: 3.6 | F12: 3.6 | G12: 3.6 | H12: 4 | I12: 1 | J12: NA/RA10% | K12: 0
A13: R. solani | B13: DSM 2044 | C13: 3 | D13: 0 | E13: 3.6 | F13: 3.6 | G13: 3.6 | H13: 4 | I13: 1 | J13: NA/RA10% | K13: 0
A14: R. solani | B14: DSM 6980 | C14: 1 | D14: 0 | E14: 3.6 | F14: 3.6 | G14: 3.6 | H14: 4 | I14: 1 | J14: NA/RA10% | K14: 0
A15: R. solani | B15: DSM 6980 | C15: 2 | D15: 0 | E15: 3.6 | F15: 3.6 | G15: 3.6 | H15: 4 | I15: 1 | J15: NA/RA10% | K15: 0
A16: R. solani | B16: DSM 6980 | C16: 3 | D16: 0 | E16: 3.6 | F16: 3.6 | G16: 3.6 | H16: 4 | I16: 1 | J16: NA/RA10% | K16: 0
A17: P. infestans | B17: Ctrl | C17: 1 | D17: 1 | E17: 3.8 | F17: 3.8 | G17: 3.8 | H17: =N$3 -> 8 | I17: 1 | J17: NA/RA10% | K17: 0
A18: P. infestans | B18: Ctrl | C18: 2 | D18: 1 | E18: 3.8 | F18: 3.8 | G18: 3.8 | H18: =N$3 -> 8 | I18: 1 | J18: NA/RA10% | K18: 0
A19: P. infestans | B19: Ctrl | C19: 3 | D19: 1 | E19: 3.8 | F19: 3.8 | G19: 3.8 | H19: =N$3 -> 8 | I19: 1 | J19: NA/RA10% | K19: 0
A20: P. infestans | B20: LEC | C20: 1 | D20: 0 | E20: 0.3 | F20: 0.3 | G20: 0.3 | H20: =N$3 -> 8 | I20: 0 | J20: NA/RA10% | K20: 0
A21: P. infestans | B21: LEC | C21: 2 | D21: 0 | H21: =N$3 -> 8 | J21: NA/RA10% | K21: 1
A22: P. infestans | B22: DSM 2043 | C22: 1 | D22: 0 | E22: 0.3 | F22: 0.3 | G22: 0.3 | H22: =N$3 -> 8 | I22: 0 | J22: NA/RA10% | K22: 0
A23: P. infestans | B23: DSM 2043 | C23: 2 | D23: 0 | E23: 0.3 | F23: 0.3 | G23: 0.3 | H23: =N$3 -> 8 | I23: 0 | J23: NA/RA10% | K23: 0
A24: P. infestans | B24: DSM 2043 | C24: 3 | D24: 0 | E24: 0.3 | F24: 0.3 | G24: 0.3 | H24: =N$3 -> 8 | I24: 0 | J24: NA/RA10% | K24: 0
A25: P. infestans | B25: DSM 2044 | C25: 1 | D25: 0 | E25: 0.4 | F25: 0.4 | G25: 0.4 | H25: =N$3 -> 8 | I25: 0 | J25: NA/RA10% | K25: 0
A26: P. infestans | B26: DSM 2044 | C26: 2 | D26: 0 | E26: 0.4 | F26: 0.4 | G26: 0.4 | H26: =N$3 -> 8 | I26: 0 | J26: NA/RA10% | K26: 0
A27: P. infestans | B27: DSM 2044 | C27: 3 | D27: 0 | E27: 0.4 | F27: 0.4 | G27: 0.4 | H27: =N$3 -> 8 | I27: 0 | J27: NA/RA10% | K27: 0
A28: P. infestans | B28: DSM 6980 | C28: 1 | D28: 0 | E28: 0.4 | F28: 0.4 | G28: 0.4 | H28: =N$3 -> 8 | I28: 0 | J28: NA/RA10% | K28: 0
A29: P. infestans | B29: DSM 6980 | C29: 2 | D29: 0 | E29: 0.4 | F29: 0.4 | G29: 0.4 | H29: =N$3 -> 8 | I29: 0 | J29: NA/RA10% | K29: 0
K32: cont.

Sheet 17_dpi
A1: Fungi | B1: Bacteria | C1: Number | D1: Ctrl | E1: GR | H1: dpi | I1: Finished | J1: Medium | K1: Cont
A2: R. solani | B2: Ctrl | C2: 1 | D2: 1 | E2: 3.6 | F2: 3.6 | G2: 3.6 | H2: 4 | I2: 1 | J2: NA/RA10% | K2: 0 | L2: Start | M2: Heute | N2: dpi
A3: R. solani | B3: Ctrl | C3: 2 | D3: 1 | E3: 3.6 | F3: 3.6 | G3: 3.6 | H3: 4 | I3: 1 | J3: NA/RA10% | K3: 0 | L3: 45950 | M3: 45967 | N3: =M3-L3 -> 17
A4: R. solani | B4: Ctrl | C4: 3 | D4: 1 | E4: 3.6 | F4: 3.6 | G4: 3.6 | H4: 4 | I4: 1 | J4: NA/RA10% | K4: 0
A5: R. solani | B5: LEC | C5: 1 | D5: 0 | E5: 2.7 | F5: 3.4 | G5: 2.9 | H5: 4 | I5: 0 | J5: NA/RA10% | K5: 0 | L5: NOTE: Only P. lingam was assessed this day.
A6: R. solani | B6: LEC | C6: 2 | D6: 0 | E6: 3 | F6: 3.2 | G6: 3 | H6: 4 | I6: 0 | J6: NA/RA10% | K6: 0
A7: R. solani | B7: LEC | C7: 3 | D7: 0 | E7: 3.9 | F7: 3.5 | G7: 3.4 | H7: 4 | I7: 0 | J7: NA/RA10% | K7: 0
A8: R. solani | B8: DSM 2043 | C8: 1 | D8: 0 | E8: 3.6 | F8: 3.6 | G8: 3.6 | H8: 4 | I8: 1 | J8: NA/RA10% | K8: 0
A9: R. solani | B9: DSM 2043 | C9: 2 | D9: 0 | E9: 3.5 | F9: 3.6 | G9: 3.6 | H9: 4 | I9: 0 | J9: NA/RA10% | K9: 0
A10: R. solani | B10: DSM 2043 | C10: 3 | D10: 0 | E10: 3.4 | F10: 3.6 | G10: 3.5 | H10: 4 | I10: 0 | J10: NA/RA10% | K10: 0
A11: R. solani | B11: DSM 2044 | C11: 1 | D11: 0 | E11: 3.6 | F11: 3.6 | G11: 3.6 | H11: 4 | I11: 1 | J11: NA/RA10% | K11: 0
A12: R. solani | B12: DSM 2044 | C12: 2 | D12: 0 | E12: 3.6 | F12: 3.6 | G12: 3.6 | H12: 4 | I12: 1 | J12: NA/RA10% | K12: 0
A13: R. solani | B13: DSM 2044 | C13: 3 | D13: 0 | E13: 3.6 | F13: 3.6 | G13: 3.6 | H13: 4 | I13: 1 | J13: NA/RA10% | K13: 0
A14: R. solani | B14: DSM 6980 | C14: 1 | D14: 0 | E14: 3.6 | F14: 3.6 | G14: 3.6 | H14: 4 | I14: 1 | J14: NA/RA10% | K14: 0
A15: R. solani | B15: DSM 6980 | C15: 2 | D15: 0 | E15: 3.6 | F15: 3.6 | G15: 3.6 | H15: 4 | I15: 1 | J15: NA/RA10% | K15: 0
A16: R. solani | B16: DSM 6980 | C16: 3 | D16: 0 | E16: 3.6 | F16: 3.6 | G16: 3.6 | H16: 4 | I16: 1 | J16: NA/RA10% | K16: 0
A17: P. lingam | B17: Ctrl | C17: 1 | D17: 1 | E17: 3.8 | F17: 3.8 | G17: 3.8 | H17: =N$3 -> 17 | I17: 1 | J17: NA/RA10% | K17: 0
A18: P. lingam | B18: Ctrl | C18: 2 | D18: 1 | E18: 3.8 | F18: 3.8 | G18: 3.8 | H18: =N$3 -> 17 | I18: 1 | J18: NA/RA10% | K18: 0
A19: P. lingam | B19: Ctrl | C19: 3 | D19: 1 | E19: 3.8 | F19: 3.8 | G19: 3.8 | H19: =N$3 -> 17 | I19: 1 | J19: NA/RA10% | K19: 0
A20: P. lingam | B20: LEC | C20: 1 | D20: 0 | E20: 1 | F20: 1.2 | G20: 1.2 | H20: =N$3 -> 17 | I20: 0 | J20: NA/RA10% | K20: 0
A21: P. lingam | B21: LEC | C21: 2 | D21: 0 | H21: =N$3 -> 17 | J21: NA/RA10% | K21: 1
A22: P. lingam | B22: LEC | C22: 3 | D22: 0 | H22: =N$3 -> 17 | J22: NA/RA10% | K22: 1
A23: P. lingam | B23: DSM 2043 | C23: 1 | D23: 0 | E23: 1 | F23: 1 | G23: 1 | H23: =N$3 -> 17 | I23: 0 | J23: NA/RA10% | K23: 0
A24: P. lingam | B24: DSM 2043 | C24: 2 | D24: 0 | E24: 1 | F24: 0.9 | G24: 1 | H24: =N$3 -> 17 | I24: 0 | J24: NA/RA10% | K24: 0
A25: P. lingam | B25: DSM 2043 | C25: 3 | D25: 0 | E25: 1.4 | F25: 1.4 | G25: 1.4 | H25: =N$3 -> 17 | I25: 0 | J25: NA/RA10% | K25: 0
A26: P. lingam | B26: DSM 2044 | C26: 1 | D26: 0 | E26: 1.1 | F26: 1 | G26: 1.1 | H26: =N$3 -> 17 | I26: 0 | J26: NA/RA10% | K26: 0
A27: P. lingam | B27: DSM 2044 | C27: 2 | D27: 0 | E27: 1.6 | F27: 1.6 | G27: 1.8 | H27: =N$3 -> 17 | I27: 0 | J27: NA/RA10% | K27: 0
A28: P. lingam | B28: DSM 2044 | C28: 3 | D28: 0 | E28: 1 | F28: 1.1 | G28: 1 | H28: =N$3 -> 17 | I28: 0 | J28: NA/RA10% | K28: 0
A29: P. lingam | B29: DSM 6980 | C29: 1 | D29: 0 | E29: 1 | F29: 1 | G29: 1.1 | H29: =N$3 -> 17 | I29: 0 | J29: NA/RA10% | K29: 0
A30: P. lingam | B30: DSM 6980 | C30: 2 | D30: 0 | H30: =N$3 -> 17 | J30: NA/RA10% | K30: 1
A31: P. lingam | B31: DSM 6980 | C31: 3 | D31: 0 | E31: 1 | F31: 1.1 | G31: 1.2 | H31: =N$3 -> 17 | I31: 0 | J31: NA/RA10% | K31: 0
A32: P. infestans | B32: Ctrl | C32: 1 | D32: 1 | E32: 3.8 | F32: 3.8 | G32: 3.8 | H32: 8 | I32: 1 | J32: NA/RA10% | K32: 0
A33: P. infestans | B33: Ctrl | C33: 2 | D33: 1 | E33: 3.8 | F33: 3.8 | G33: 3.8 | H33: 8 | I33: 1 | J33: NA/RA10% | K33: 0
A34: P. infestans | B34: Ctrl | C34: 3 | D34: 1 | E34: 3.8 | F34: 3.8 | G34: 3.8 | H34: 8 | I34: 1 | J34: NA/RA10% | K34: 0
A35: P. infestans | B35: LEC | C35: 1 | D35: 0 | E35: 0.3 | F35: 0.3 | G35: 0.3 | H35: 8 | I35: 0 | J35: NA/RA10% | K35: 0
A36: P. infestans | B36: LEC | C36: 2 | D36: 0 | H36: 8 | J36: NA/RA10% | K36: 1
A37: P. infestans | B37: DSM 2043 | C37: 1 | D37: 0 | E37: 0.3 | F37: 0.3 | G37: 0.3 | H37: 8 | I37: 0 | J37: NA/RA10% | K37: 0
A38: P. infestans | B38: DSM 2043 | C38: 2 | D38: 0 | E38: 0.3 | F38: 0.3 | G38: 0.3 | H38: 8 | I38: 0 | J38: NA/RA10% | K38: 0
A39: P. infestans | B39: DSM 2043 | C39: 3 | D39: 0 | E39: 0.3 | F39: 0.3 | G39: 0.3 | H39: 8 | I39: 0 | J39: NA/RA10% | K39: 0
A40: P. infestans | B40: DSM 2044 | C40: 1 | D40: 0 | E40: 0.4 | F40: 0.4 | G40: 0.4 | H40: 8 | I40: 0 | J40: NA/RA10% | K40: 0
...

Sheet Summary
A1: Fungi | B1: Bacteria | C1: Number | D1: Ctrl | E1: GR | H1: dpi | I1: Finished | J1: Medium | K1: Cont
A2: R. solani | B2: Ctrl | C2: 1 | D2: 1 | E2: 3.6 | F2: 3.6 | G2: 3.6 | H2: 4 | I2: 1 | J2: NA/RA10% | K2: 0 | L2: =AVERAGE(E2:G2) -> 3.6 | M2: =AVERAGE(L2:L4) -> 3.6 | N2: =ROUND(M2,1) -> 3.6
A3: R. solani | B3: Ctrl | C3: 2 | D3: 1 | E3: 3.6 | F3: 3.6 | G3: 3.6 | H3: 4 | I3: 1 | J3: NA/RA10% | K3: 0 | L3: =AVERAGE(E3:G3) -> 3.6
A4: R. solani | B4: Ctrl | C4: 3 | D4: 1 | E4: 3.6 | F4: 3.6 | G4: 3.6 | H4: 4 | I4: 1 | J4: NA/RA10% | K4: 0 | L4: =AVERAGE(E4:G4) -> 3.6
A5: R. solani | B5: LEC | C5: 1 | D5: 0 | E5: 2.7 | F5: 3.4 | G5: 2.9 | H5: 4 | I5: 0 | J5: NA/RA10% | K5: 0 | L5: =AVERAGE(E5:G5) -> 3 | M5: =AVERAGE(L5:L7) -> 3.2222222 | N5: =ROUND(M5,1) -> 3.2
A6: R. solani | B6: LEC | C6: 2 | D6: 0 | E6: 3 | F6: 3.2 | G6: 3 | H6: 4 | I6: 0 | J6: NA/RA10% | K6: 0 | L6: =AVERAGE(E6:G6) -> 3.0666667
A7: R. solani | B7: LEC | C7: 3 | D7: 0 | E7: 3.9 | F7: 3.5 | G7: 3.4 | H7: 4 | I7: 0 | J7: NA/RA10% | K7: 0 | L7: =AVERAGE(E7:G7) -> 3.6
A8: R. solani | B8: DSM 2043 | C8: 1 | D8: 0 | E8: 3.6 | F8: 3.6 | G8: 3.6 | H8: 4 | I8: 1 | J8: NA/RA10% | K8: 0 | L8: =AVERAGE(E8:G8) -> 3.6 | M8: =AVERAGE(L8:L10) -> 3.5555556 | N8: =ROUND(M8,1) -> 3.6
A9: R. solani | B9: DSM 2043 | C9: 2 | D9: 0 | E9: 3.5 | F9: 3.6 | G9: 3.6 | H9: 4 | I9: 0 | J9: NA/RA10% | K9: 0 | L9: =AVERAGE(E9:G9) -> 3.5666667
A10: R. solani | B10: DSM 2043 | C10: 3 | D10: 0 | E10: 3.4 | F10: 3.6 | G10: 3.5 | H10: 4 | I10: 0 | J10: NA/RA10% | K10: 0 | L10: =AVERAGE(E10:G10) -> 3.5
A11: R. solani | B11: DSM 2044 | C11: 1 | D11: 0 | E11: 3.6 | F11: 3.6 | G11: 3.6 | H11: 4 | I11: 1 | J11: NA/RA10% | K11: 0 | L11: =AVERAGE(E11:G11) -> 3.6 | M11: =AVERAGE(L11:L13) -> 3.6 | N11: =ROUND(M11,1) -> 3.6
A12: R. solani | B12: DSM 2044 | C12: 2 | D12: 0 | E12: 3.6 | F12: 3.6 | G12: 3.6 | H12: 4 | I12: 1 | J12: NA/RA10% | K12: 0 | L12: =AVERAGE(E12:G12) -> 3.6
A13: R. solani | B13: DSM 2044 | C13: 3 | D13: 0 | E13: 3.6 | F13: 3.6 | G13: 3.6 | H13: 4 | I13: 1 | J13: NA/RA10% | K13: 0 | L13: =AVERAGE(E13:G13) -> 3.6
A14: R. solani | B14: DSM 6980 | C14: 1 | D14: 0 | E14: 3.6 | F14: 3.6 | G14: 3.6 | H14: 4 | I14: 1 | J14: NA/RA10% | K14: 0 | L14: =AVERAGE(E14:G14) -> 3.6 | M14: =AVERAGE(L14:L16) -> 3.6 | N14: =ROUND(M14,1) -> 3.6
A15: R. solani | B15: DSM 6980 | C15: 2 | D15: 0 | E15: 3.6 | F15: 3.6 | G15: 3.6 | H15: 4 | I15: 1 | J15: NA/RA10% | K15: 0 | L15: =AVERAGE(E15:G15) -> 3.6
A16: R. solani | B16: DSM 6980 | C16: 3 | D16: 0 | E16: 3.6 | F16: 3.6 | G16: 3.6 | H16: 4 | I16: 1 | J16: NA/RA10% | K16: 0 | L16: =AVERAGE(E16:G16) -> 3.6
A17: P. lingam | B17: Ctrl | C17: 1 | D17: 1 | E17: 3.8 | F17: 3.8 | G17: 3.8 | H17: 17 | I17: 1 | J17: NA/RA10% | K17: 0 | L17: =AVERAGE(E17:G17) -> 3.8 | M17: =AVERAGE(L17:L19) -> 3.8 | N17: =ROUND(M17,1) -> 3.8
A18: P. lingam | B18: Ctrl | C18: 2 | D18: 1 | E18: 3.8 | F18: 3.8 | G18: 3.8 | H18: 17 | I18: 1 | J18: NA/RA10% | K18: 0 | L18: =AVERAGE(E18:G18) -> 3.8
A19: P. lingam | B19: Ctrl | C19: 3 | D19: 1 | E19: 3.8 | F19: 3.8 | G19: 3.8 | H19: 17 | I19: 1 | J19: NA/RA10% | K19: 0 | L19: =AVERAGE(E19:G19) -> 3.8
A20: P. lingam | B20: LEC | C20: 1 | D20: 0 | E20: 1 | F20: 1.2 | G20: 1.2 | H20: 17 | I20: 0 | J20: NA/RA10% | K20: 0 | L20: =AVERAGE(E20:G20) -> 1.1333333 | M20: =AVERAGE(L20) -> 1.1333333 | N20: =ROUND(M20,1) -> 1.1
A21: P. lingam | B21: LEC | C21: 2 | D21: 0 | H21: 17 | J21: NA/RA10% | K21: 1
A22: P. lingam | B22: LEC | C22: 3 | D22: 0 | H22: 17 | J22: NA/RA10% | K22: 1
A23: P. lingam | B23: DSM 2043 | C23: 1 | D23: 0 | E23: 1 | F23: 1 | G23: 1 | H23: 17 | I23: 0 | J23: NA/RA10% | K23: 0 | L23: =AVERAGE(E23:G23) -> 1 | M23: =AVERAGE(L23:L25) -> 1.1222222 | N23: =ROUND(M23,1) -> 1.1
A24: P. lingam | B24: DSM 2043 | C24: 2 | D24: 0 | E24: 1 | F24: 0.9 | G24: 1 | H24: 17 | I24: 0 | J24: NA/RA10% | K24: 0 | L24: =AVERAGE(E24:G24) -> 0.96666667
A25: P. lingam | B25: DSM 2043 | C25: 3 | D25: 0 | E25: 1.4 | F25: 1.4 | G25: 1.4 | H25: 17 | I25: 0 | J25: NA/RA10% | K25: 0 | L25: =AVERAGE(E25:G25) -> 1.4
A26: P. lingam | B26: DSM 2044 | C26: 4 | D26: 0 | E26: 0.8 | F26: 0.9 | G26: 0.9 | H26: 17 | I26: 0 | J26: NA/RA10% | K26: 0 | L26: =AVERAGE(E26:G26) -> 0.86666667 | M26: =AVERAGE(L26:L28) -> 0.98888889 | N26: =ROUND(M26,1) -> 1
A27: P. lingam | B27: DSM 2044 | C27: 1 | D27: 0 | E27: 1.1 | F27: 1 | G27: 1.1 | H27: 17 | I27: 0 | J27: NA/RA10% | K27: 0 | L27: =AVERAGE(E27:G27) -> 1.0666667
A28: P. lingam | B28: DSM 2044 | C28: 3 | D28: 0 | E28: 1 | F28: 1.1 | G28: 1 | H28: 17 | I28: 0 | J28: NA/RA10% | K28: 0 | L28: =AVERAGE(E28:G28) -> 1.0333333
A29: P. lingam | B29: DSM 6980 | C29: 1 | D29: 0 | E29: 1 | F29: 1 | G29: 1.1 | H29: 17 | I29: 0 | J29: NA/RA10% | K29: 0 | L29: =AVERAGE(E29:G29) -> 1.0333333 | M29: =AVERAGE(L29:L31) -> 1.0666667 | N29: =ROUND(M29,1) -> 1.1
A30: P. lingam | B30: DSM 6980 | C30: 2 | D30: 0 | H30: 17 | J30: NA/RA10% | K30: 1
A31: P. lingam | B31: DSM 6980 | C31: 3 | D31: 0 | E31: 1 | F31: 1.1 | G31: 1.2 | H31: 17 | I31: 0 | J31: NA/RA10% | K31: 0 | L31: =AVERAGE(E31:G31) -> 1.1
A32: P. infestans | B32: Ctrl | C32: 1 | D32: 1 | E32: 3.8 | F32: 3.8 | G32: 3.8 | H32: 8 | I32: 1 | J32: NA/RA10% | K32: 0 | L32: =AVERAGE(E32:G32) -> 3.8 | M32: =AVERAGE(L32:L34) -> 3.8 | N32: =ROUND(M32,1) -> 3.8
A33: P. infestans | B33: Ctrl | C33: 2 | D33: 1 | E33: 3.8 | F33: 3.8 | G33: 3.8 | H33: 8 | I33: 1 | J33: NA/RA10% | K33: 0 | L33: =AVERAGE(E33:G33) -> 3.8
A34: P. infestans | B34: Ctrl | C34: 3 | D34: 1 | E34: 3.8 | F34: 3.8 | G34: 3.8 | H34: 8 | I34: 1 | J34: NA/RA10% | K34: 0 | L34: =AVERAGE(E34:G34) -> 3.8
A35: P. infestans | B35: LEC | C35: 1 | D35: 0 | E35: 0.3 | F35: 0.3 | G35: 0.3 | H35: 8 | I35: 0 | J35: NA/RA10% | K35: 0 | L35: =AVERAGE(E35:G35) -> 0.3 | M35: =AVERAGE(L35) -> 0.3 | N35: =ROUND(M35,1) -> 0.3
A36: P. infestans | B36: LEC | C36: 2 | D36: 0 | H36: 8 | J36: NA/RA10% | K36: 1
A37: P. infestans | B37: DSM 2043 | C37: 1 | D37: 0 | E37: 0.3 | F37: 0.3 | G37: 0.3 | H37: 8 | I37: 0 | J37: NA/RA10% | K37: 0 | L37: =AVERAGE(E37:G37) -> 0.3 | M37: =AVERAGE(L37:L39) -> 0.3 | N37: =ROUND(M37,1) -> 0.3
A38: P. infestans | B38: DSM 2043 | C38: 2 | D38: 0 | E38: 0.3 | F38: 0.3 | G38: 0.3 | H38: 8 | I38: 0 | J38: NA/RA10% | K38: 0 | L38: =AVERAGE(E38:G38) -> 0.3
A39: P. infestans | B39: DSM 2043 | C39: 3 | D39: 0 | E39: 0.3 | F39: 0.3 | G39: 0.3 | H39: 8 | I39: 0 | J39: NA/RA10% | K39: 0 | L39: =AVERAGE(E39:G39) -> 0.3
A40: P. infestans | B40: DSM 2044 | C40: 1 | D40: 0 | E40: 0.4 | F40: 0.4 | G40: 0.4 | H40: 8 | I40: 0 | J40: NA/RA10% | K40: 0 | L40: =AVERAGE(E40:G40) -> 0.4 | M40: =AVERAGE(L40:L42) -> 0.4 | N40: =ROUND(M40,1) -> 0.4
...

Sheet TableS5
A1: Fungi | B1: Bacteria | C1: Isolate | D1: Growth reduction [%] | E1: n
A2: R. solani | B2: L. enzymogenes | C2: DSM 2043 | D2: =(Summary!N8-Summary!N$2)/Summary!N$2*100 -> 0 | E2: =COUNT(Summary!L8:L10) -> 3
A3: R. solani | B3: L. antibioticus | C3: DSM 2044 | D3: =(Summary!N11-Summary!N$2)/Summary!N$2*100 -> 0 | E3: =COUNT(Summary!L11:L13) -> 3
A4: R. solani | B4: L. gummosus | C4: DSM 6980 | D4: =(Summary!N14-Summary!N$2)/Summary!N$2*100 -> 0 | E4: =COUNT(Summary!L14:L16) -> 3
A5: P. infestans | B5: L. enzymogenes | C5: DSM 2043 | D5: =(Summary!N37-Summary!N$32)/Summary!N$32*-100 -> 92.105263 | E5: =COUNT(Summary!L37:L39) -> 3
A6: P. infestans | B6: L. antibioticus | C6: DSM 2044 | D6: =(Summary!N40-Summary!N$32)/Summary!N$32*-100 -> 89.473684 | E6: =COUNT(Summary!L40:L42) -> 3
A7: P. infestans | B7: L. gummosus | C7: DSM 6980 | D7: =(Summary!N43-Summary!N$32)/Summary!N$32*-100 -> 89.473684 | E7: =COUNT(Summary!L43:L44) -> 2
A8: P. lingam | B8: L. enzymogenes | C8: DSM 2043 | D8: =(Summary!N23-Summary!N$17)/Summary!N$17*-100 -> 71.052632 | E8: =COUNT(Summary!L22:L25) -> 3
A9: P. lingam | B9: L. antibioticus | C9: DSM 2044 | D9: =(Summary!N26-Summary!N$17)/Summary!N$17*-100 -> 73.684211 | E9: =COUNT(Summary!L26:L28) -> 3
A10: P. lingam | B10: L. gummosus | C10: DSM 6980 | D10: =(Summary!N29-Summary!N$17)/Summary!N$17*-100 -> 71.052632 | E10: =COUNT(Summary!L29:L31) -> 2
